Workbook

Sheet Contents
A1: Australian Bureau of Statistics
A2: 45130DO013_202223 Criminal Courts, Australia, 2022–23
A3: Released at 11:30 am (Canberra time) Fri 15 March 2024
B5: Contents
B6: Tables
B7: 65 | C7: Defendants with a guilty outcome, Selected principal sentence by sentence length and court level, 2022–23
B8: 66 | C8: Defendants sentenced to custody in a correctional institution – All Courts, Principal offence by sentence length, States and territories, 2022–23
B9: 67 | C9: Defendants sentenced to custody in a correctional institution – Higher Courts, Selected principal offence by sentence length, States and territories, 2022–23
B10: 68 | C10: Defendants sentenced to custody in a correctional institution – Magistrates' Courts, Selected principal offence by sentence length, States and territories, 2022–23
B11: 69 | C11: Defendants sentenced to custody in a correctional institution – Children's Courts, Selected principal offence by sentence length, States and territories, 2022–23
B12: 70 | C12: Defendants sentenced to community service / work, Selected principal offence by sentence length and court level, States and territories, 2022–23
B13: 71 | C13: Defendants given a fine, Selected principal offence by value of fine and court level, States and territories, 2022–23
B14: 72 | C14: Defendants sentenced to custody in a correctional institution (excluding traffic offences), Selected principal offence by Indigenous status and sentence length, Selected states and territories, 2022–23
B17: More information available from the ABS website
B18: Criminal Courts, Australia, 2022–23
B20: Commentary
B21: Methodology
B24: Inquiries
B26: For further information about these and related statistics, contact the ABS Consultancy Service on 1300 135 070, or email information.consultancy@abs.gov.au. The ABS Privacy Policy outlines how the ABS will handle any personal information that you provide to us.
B30: © Commonwealth of Australia 2024

Sheet Table 65
A1: Australian Bureau of Statistics
A2: =Contents!A2 -> 45130DO013_202223 Criminal Courts, Australia, 2022–23
A3: =Contents!A3 -> Released at 11:30 am (Canberra time) Fri 15 March 2024
A4: Table 65 Defendants with a guilty outcome, Selected principal sentence by sentence length and court level, 2022–23
B5: All Courts | L5: Higher Courts | N5: Magistrates' Courts | P5: Children's Courts
B6: Under 3 months | C6: 3 to under 6 months | D6: 6 to under 12 months | E6: 1 to under 2 years | F6: 2 to under 5 years | G6: 5 to under 10 years | H6: 10 years & over | I6: Total | J6: Mean | K6: Median | L6: Mean | M6: Median | N6: Mean | O6: Median | P6: Mean | Q6: Median
A7: Selected principal sentence | B7: (no.) | C7: (no.) | D7: (no.) | E7: (no.) | F7: (no.) | G7: (no.) | H7: (no.) | I7: (no.) | J7: (months) | K7: (months) | L7: (months) | M7: (months) | N7: (months) | O7: (months) | P7: (months) | Q7: (months)
A8: Custody in a correctional institution | B8: 7071 | C8: 7288 | D8: 10757 | E8: 8860 | F8: 5681 | G8: 1383 | H8: 351 | I8: 43075 | J8: 14.6 | K8: 8 | L8: 40.1 | M8: 32.3 | N8: 7.4 | O8: 6 | P8: 7.6 | Q8: 6
A9: Imprisonment | B9: 6893 | C9: 7081 | D9: 10456 | E9: 8652 | F9: 5637 | G9: 1377 | H9: 349 | I9: 42129 | J9: 14.7 | K9: 8 | L9: 40.1 | M9: 33 | N9: 7.4 | O9: 6 | P9: 6.9 | Q9: 4
A10: Life & Indeterminate imprisonment | B10: 0 | C10: 0 | D10: 0 | E10: 0 | F10: 0 | G10: 0 | H10: 51 | I10: 51
A11: Imprisonment with determined term | B11: 6500 | C11: 6286 | D11: 9577 | E11: 8180 | F11: 5126 | G11: 1326 | H11: 299 | I11: 37340 | J11: 14.9 | K11: 8 | L11: 41.3 | M11: 34 | N11: 7.5 | O11: 6 | P11: 7.1 | Q11: 4
A12: Imprisonment with partially suspended term | B12: 392 | C12: 791 | D12: 877 | E12: 475 | F12: 515 | G12: 54 | H12: 0 | I12: 3098 | J12: 12.3 | K12: 7 | L12: 28.9 | M12: 24 | N12: 6 | O12: 5
A14: Juvenile detention | B14: 183 | C14: 209 | D14: 298 | E14: 204 | F14: 40 | G14: 6 | H14: 3 | I14: 940 | J14: 9 | K14: 6 | L14: 28.7 | M14: 18 | N14: 6.2 | O14: 4.5 | P14: 7.7 | Q14: 6
A15: Juvenile detention with determined term | B15: 134 | C15: 104 | D15: 161 | E15: 145 | F15: 25 | G15: 3 | H15: 0 | I15: 580 | J15: 8.6 | K15: 6.9 | L15: 26 | M15: 20 | N15: 6.2 | O15: 4.5 | P15: 7.5 | Q15: 6
A16: Juvenile detention with partially suspended term | B16: 45 | C16: 104 | D16: 137 | E16: 60 | F16: 16 | G16: 5 | H16: 3 | I16: 363 | J16: 9.7 | K16: 6 | L16: 32 | M16: 16 | N16: 0 | O16: 0 | P16: 7.9 | Q16: 6
A18: Intensive penalty in the community | B18: 358 | C18: 1028 | D18: 4144 | E18: 3228 | F18: 571 | G18: 3 | H18: 0 | I18: 9352 | J18: 10.7 | K18: 9 | L18: 22.6 | M18: 22 | N18: 9.7 | O18: 9 | P18: 6.5 | Q18: 6
A20: Fully suspended sentence | B20: 3542 | C20: 3479 | D20: 3820 | E20: 1278 | F20: 388 | G20: 29 | H20: 0 | I20: 12549 | J20: 6.1 | K20: 4 | L20: 18.5 | M20: 15 | N20: 4.8 | O20: 4 | P20: 3.8 | Q20: 3
A21: Fully suspended adult sentence | B21: 3507 | C21: 3199 | D21: 3793 | E21: 1264 | F21: 391 | G21: 29 | H21: 0 | I21: 12182 | J21: 6.2 | K21: 4 | L21: 18.5 | M21: 15 | N21: 4.8 | O21: 4 | P21: 6.7 | Q21: 6
A22: Fully suspended juvenile sentence | B22: 41 | C22: 280 | D22: 27 | E22: 17 | F22: 3 | G22: 0 | H22: 0 | I22: 367 | J22: 3.9 | K22: 3 | L22: 16 | M22: 16.5 | N22: 0 | O22: 0 | P22: 3.7 | Q22: 3
A24: Moderate penalty in the community | B24: 41 | C24: 939 | D24: 8068 | E24: 19083 | F24: 3677 | G24: 0 | H24: 0 | I24: 35451 | J24: 13.3 | K24: 12 | L24: 20.9 | M24: 24 | N24: 13.8 | O24: 12 | P24: 8.5 | Q24: 8
A25: Good behaviour (incl. bonds) | B25: 797 | C25: 5764 | D25: 14981 | E25: 27042 | F25: 3444 | G25: 3 | H25: 0 | I25: 53115 | J25: 10.7 | K25: 12 | L25: 17.3 | M25: 18 | N25: 10.9 | O25: 12 | P25: 6.5 | Q25: 6
A28: © Commonwealth of Australia 2024

Sheet Table 66
A1: Australian Bureau of Statistics
A2: =Contents!A2 -> 45130DO013_202223 Criminal Courts, Australia, 2022–23
A3: =Contents!A3 -> Released at 11:30 am (Canberra time) Fri 15 March 2024
A4: Table 66 Defendants sentenced to custody in a correctional institution – All Courts, Principal offence by sentence length, States and territories, 2022–23
B5: Under 3 months | C5: 3 to under 6 months | D5: 6 to under 12 months | E5: 1 to under 2 years | F5: 2 to under 5 years | G5: 5 to under 10 years | H5: 10 years & over | I5: Total | J5: Mean | K5: Median
A6: Principal offence | B6: (no.) | C6: (no.) | D6: (no.) | E6: (no.) | F6: (no.) | G6: (no.) | H6: (no.) | I6: (no.) | J6: (months) | K6: (months)
B7: Australia
A8: 01 Homicide and related offences | B8: 0 | C8: 0 | D8: 0 | E8: 13 | F8: 48 | G8: 112 | H8: 127 | I8: 293 | J8: 120.6 | K8: 96
A9: 02 Acts intended to cause injury | B9: 1341 | C9: 2402 | D9: 3603 | E9: 3143 | F9: 1287 | G9: 195 | H9: 12 | I9: 12170 | J9: 12 | K9: 9
A10: 021 Assault | B10: 1232 | C10: 2186 | D10: 3161 | E10: 2826 | F10: 1224 | G10: 193 | H10: 12 | I10: 11018 | J10: 12.2 | K10: 9
A11: 03 Sexual assault and related offences | B11: 55 | C11: 106 | D11: 272 | E11: 548 | F11: 778 | G11: 456 | H11: 113 | I11: 2327 | J11: 39.5 | K11: 28
A12: 031 Sexual assault | B12: 22 | C12: 51 | D12: 158 | E12: 301 | F12: 573 | G12: 426 | H12: 109 | I12: 1639 | J12: 47.3 | K12: 36
A13: 04 Dangerous/negligent acts | B13: 170 | C13: 306 | D13: 695 | E13: 625 | F13: 240 | G13: 29 | H13: 0 | I13: 2096 | J13: 12.5 | K13: 9
A14: 05 Abduction/harassment | B14: 145 | C14: 141 | D14: 190 | E14: 97 | F14: 90 | G14: 20 | H14: 3 | I14: 688 | J14: 12.6 | K14: 6
A15: 053 Harassment and threatening behaviour | B15: 135 | C15: 136 | D15: 171 | E15: 69 | F15: 16 | G15: 0 | H15: 0 | I15: 531 | J15: 6.5 | K15: 5
A16: 06 Robbery/extortion | B16: 45 | C16: 61 | D16: 139 | E16: 235 | F16: 673 | G16: 101 | H16: 0 | I16: 1257 | J16: 29.4 | K16: 30
A17: 061 Robbery | B17: 37 | C17: 53 | D17: 133 | E17: 225 | F17: 666 | G17: 99 | H17: 0 | I17: 1226 | J17: 29.6 | K17: 30
A18: 07 Unlawful entry with intent | B18: 343 | C18: 469 | D18: 1063 | E18: 1433 | F18: 849 | G18: 47 | H18: 4 | I18: 4305 | J18: 14.9 | K18: 12
A19: 08 Theft | B19: 1172 | C19: 883 | D19: 1111 | E19: 620 | F19: 144 | G19: 15 | H19: 0 | I19: 4131 | J19: 7 | K19: 5
... A41: All principal offences | B41: 7071 | C41: 7288 | D41: 10757 | E41: 8860 | F41: 5681 | G41: 1383 | H41: 351 | I41: 43075 | J41: 14.6 | K41: 8
A42: All principal offences (%) | B42: 16.4 | C42: 16.9 | D42: 25 | E42: 20.6 | F42: 13.2 | G42: 3.2 | H42: 0.8 | I42: 100 | J42: .. | K42: ..
B43: New South Wales
A44: 01 Homicide and related offences | B44: 0 | C44: 0 | D44: 0 | E44: 0 | F44: 11 | G44: 18 | H44: 46 | I44: 84 | J44: 163.5 | K44: 153
A45: 02 Acts intended to cause injury | B45: 189 | C45: 483 | D45: 1264 | E45: 1314 | F45: 240 | G45: 36 | H45: 0 | I45: 3527 | J45: 11.7 | K45: 10
A46: 03 Sexual assault and related offences | B46: 5 | C46: 13 | D46: 83 | E46: 209 | F46: 285 | G46: 149 | H46: 38 | I46: 798 | J46: 40.4 | K46: 30
A47: 04 Dangerous/negligent acts | B47: 4 | C47: 43 | D47: 185 | E47: 250 | F47: 42 | G47: 0 | H47: 0 | I47: 528 | J47: 12.5 | K47: 12
A48: 05 Abduction/harassment | B48: 16 | C48: 24 | D48: 37 | E48: 30 | F48: 48 | G48: 15 | H48: 0 | I48: 162 | J48: 23.1 | K48: 12
A49: 06 Robbery/extortion | B49: 0 | C49: 9 | D49: 26 | E49: 54 | F49: 167 | G49: 23 | H49: 0 | I49: 282 | J49: 32.8 | K49: 34
A50: 07 Unlawful entry with intent | B50: 5 | C50: 42 | D50: 249 | E50: 416 | F50: 177 | G50: 13 | H50: 4 | I50: 907 | J50: 16.9 | K50: 13
A51: 08 Theft | B51: 238 | C51: 327 | D51: 421 | E51: 195 | F51: 33 | G51: 6 | H51: 0 | I51: 1216 | J51: 7.4 | K51: 6
A52: 09 Fraud/deception | B52: 43 | C52: 72 | D52: 88 | E52: 93 | F52: 28 | G52: 4 | H52: 0 | I52: 332 | J52: 11.6 | K52: 8
A53: 10 Illicit drug offences | B53: 38 | C53: 47 | D53: 127 | E53: 199 | F53: 242 | G53: 92 | H53: 17 | I53: 762 | J53: 30.1 | K53: 18
A54: 11 Weapons/explosives | B54: 63 | C54: 78 | D54: 107 | E54: 101 | F54: 62 | G54: 14 | H54: 0 | I54: 417 | J54: 13.4 | K54: 8
A55: 12 Property damage and environmental pollution | B55: 40 | C55: 51 | D55: 81 | E55: 66 | F55: 19 | G55: 0 | H55: 0 | I55: 255 | J55: 9.7 | K55: 8
... A60: All principal offences | B60: 948 | C60: 1678 | D60: 3511 | E60: 3250 | F60: 1400 | G60: 381 | H60: 112 | I60: 11281 | J60: 16 | K60: 10
A61: All principal offences (%) | B61: 8.4 | C61: 14.9 | D61: 31.1 | E61: 28.8 | F61: 12.4 | G61: 3.4 | H61: 1 | I61: 100 | J61: .. | K61: ..
B62: Victoria
A63: 01 Homicide and related offences | B63: 0 | C63: 0 | D63: 0 | E63: 5 | F63: 15 | G63: 25 | H63: 25 | I63: 69 | J63: 117.1 | K63: 90
A64: 02 Acts intended to cause injury | B64: 628 | C64: 455 | D64: 335 | E64: 165 | F64: 77 | G64: 33 | H64: 3 | I64: 1696 | J64: 8.1 | K64: 3.9
A65: 03 Sexual assault and related offences | B65: 31 | C65: 51 | D65: 49 | E65: 38 | F65: 106 | G65: 98 | H65: 16 | I65: 399 | J65: 39.5 | K65: 29
...

Sheet Table 67
A1: Australian Bureau of Statistics
A2: =Contents!A2 -> 45130DO013_202223 Criminal Courts, Australia, 2022–23
A3: =Contents!A3 -> Released at 11:30 am (Canberra time) Fri 15 March 2024
A4: Table 67 Defendants sentenced to custody in a correctional institution – Higher Courts, Selected principal offence by sentence length, States and territories, 2022–23
B5: Under 1 year | C5: 1 to under 2 years | D5: 2 to under 3 years | E5: 3 to under 4 years | F5: 4 to under 5 years | G5: 5 to under 10 years | H5: 10 years & over | I5: Total | J5: Mean | K5: Median
A6: Selected principal offence | B6: (no.) | C6: (no.) | D6: (no.) | E6: (no.) | F6: (no.) | G6: (no.) | H6: (no.) | I6: (no.) | J6: (months) | K6: (months)
B7: Australia
A8: 01 Homicide and related offences | B8: 0 | C8: 3 | D8: 16 | E8: 13 | F8: 9 | G8: 107 | H8: 127 | I8: 290 | J8: 123.7 | K8: 96
A9: 011 Murder | B9: 0 | C9: 0 | D9: 0 | E9: 0 | F9: 0 | G9: 4 | H9: 93 | I9: 99 | J9: 237.9 | K9: 240
A10: 013 Manslaughter and driving causing death | B10: 0 | C10: 3 | D10: 16 | E10: 13 | F10: 9 | G10: 101 | H10: 22 | I10: 171 | J10: 78.6 | K10: 82.5
A11: 02 Acts intended to cause injury | B11: 211 | C11: 409 | D11: 498 | E11: 376 | F11: 129 | G11: 195 | H11: 12 | I11: 1822 | J11: 32.5 | K11: 30
A12: 021 Assault | B12: 200 | C12: 383 | D12: 474 | E12: 365 | F12: 127 | G12: 190 | H12: 12 | I12: 1747 | J12: 32.8 | K12: 30
A13: 03 Sexual assault and related offences | B13: 140 | C13: 348 | D13: 298 | E13: 247 | F13: 198 | G13: 451 | H13: 113 | I13: 1799 | J13: 48.1 | K13: 36
A14: 031 Sexual assault | B14: 73 | C14: 179 | D14: 190 | E14: 187 | F14: 167 | G14: 427 | H14: 109 | I14: 1326 | J14: 55.7 | K14: 48
A15: 04 Dangerous/negligent acts | B15: 19 | C15: 50 | D15: 73 | E15: 39 | F15: 26 | G15: 29 | H15: 0 | I15: 235 | J15: 34.3 | K15: 30
A16: 05 Abduction/harassment | B16: 30 | C16: 32 | D16: 35 | E16: 25 | F16: 22 | G16: 20 | H16: 3 | I16: 170 | J16: 33.7 | K16: 30
A17: 051 Abduction and kidnapping | B17: 3 | C17: 5 | D17: 21 | E17: 26 | F17: 19 | G17: 17 | H17: 3 | I17: 90 | J17: 46.1 | K17: 42
A18: 06 Robbery/extortion | B18: 84 | C18: 158 | D18: 252 | E18: 308 | F18: 101 | G18: 101 | H18: 0 | I18: 1011 | J18: 34.1 | K18: 36
A19: 061 Robbery | B19: 78 | C19: 151 | D19: 244 | E19: 310 | F19: 100 | G19: 99 | H19: 0 | I19: 987 | J19: 34.5 | K19: 36
... A33: All principal offences | B33: 935 | C33: 1778 | D33: 2064 | E33: 1792 | F33: 841 | G33: 1378 | H33: 351 | I33: 9154 | J33: 40.1 | K33: 32.3
A34: All principal offences (%) | B34: 10.2 | C34: 19.4 | D34: 22.5 | E34: 19.6 | F34: 9.2 | G34: 15.1 | H34: 3.8 | I34: 100 | J34: .. | K34: ..
B35: New South Wales
A36: 01 Homicide and related offences | B36: 0 | C36: 0 | D36: 3 | E36: 3 | F36: 0 | G36: 18 | H36: 46 | I36: 79 | J36: 169.3 | K36: 156
A37: 02 Acts intended to cause injury | B37: 21 | C37: 62 | D37: 75 | E37: 60 | F37: 17 | G37: 36 | H37: 0 | I37: 267 | J37: 34 | K37: 30
A38: 03 Sexual assault and related offences | B38: 16 | C38: 47 | D38: 113 | E38: 99 | F38: 64 | G38: 149 | H38: 38 | I38: 528 | J38: 54.6 | K38: 44
A39: 04 Dangerous/negligent acts | B39: 0 | C39: 4 | D39: 16 | E39: 4 | F39: 0 | G39: 0 | H39: 0 | I39: 30 | J39: 27 | K39: 27
A40: 05 Abduction/harassment | B40: 0 | C40: 9 | D40: 16 | E40: 18 | F40: 12 | G40: 15 | H40: 0 | I40: 64 | J40: 47.2 | K40: 42
A41: 06 Robbery/extortion | B41: 0 | C41: 8 | D41: 56 | E41: 87 | F41: 24 | G41: 23 | H41: 0 | I41: 200 | J41: 41 | K41: 36
A42: 07 Unlawful entry with intent | B42: 3 | C42: 34 | D42: 87 | E42: 38 | F42: 21 | G42: 13 | H42: 4 | I42: 199 | J42: 34.1 | K42: 30
A43: 08 Theft | B43: 3 | C43: 18 | D43: 18 | E43: 7 | F43: 0 | G43: 6 | H43: 0 | I43: 52 | J43: 32.2 | K43: 27
A44: 09 Fraud/deception | B44: 4 | C44: 7 | D44: 11 | E44: 9 | F44: 3 | G44: 4 | H44: 0 | I44: 33 | J44: 40.7 | K44: 34.5
A45: 10 Illicit drug offences | B45: 3 | C45: 24 | D45: 72 | E45: 86 | F45: 59 | G45: 92 | H45: 17 | I45: 362 | J45: 51.7 | K45: 45
A46: 11 Weapons/explosives | B46: 0 | C46: 4 | D46: 17 | E46: 27 | F46: 8 | G46: 14 | H46: 0 | I46: 67 | J46: 41 | K46: 36
A47: 12 Property damage and environmental pollution | B47: 0 | C47: 0 | D47: 3 | E47: 7 | F47: 0 | G47: 0 | H47: 0 | I47: 11 | J47: 35.1 | K47: 36
... A49: All principal offences | B49: 58 | C49: 251 | D49: 495 | E49: 451 | F49: 211 | G49: 381 | H49: 112 | I49: 1962 | J49: 49.4 | K49: 36
A50: All principal offences (%) | B50: 3 | C50: 12.8 | D50: 25.2 | E50: 23 | F50: 10.8 | G50: 19.4 | H50: 5.7 | I50: 100 | J50: .. | K50: ..
B51: Victoria
A52: 01 Homicide and related offences | B52: 0 | C52: 5 | D52: 7 | E52: 4 | F52: 0 | G52: 25 | H52: 25 | I52: 69 | J52: 117.1 | K52: 90
A53: 02 Acts intended to cause injury | B53: 75 | C53: 45 | D53: 20 | E53: 27 | F53: 22 | G53: 33 | H53: 3 | I53: 233 | J53: 30.5 | K53: 20
A54: 03 Sexual assault and related offences | B54: 14 | C54: 30 | D54: 36 | E54: 40 | F54: 29 | G54: 98 | H54: 16 | I54: 263 | J54: 57 | K54: 51
...

Sheet Table 68
A1: Australian Bureau of Statistics
A2: =Contents!A2 -> 45130DO013_202223 Criminal Courts, Australia, 2022–23
A3: =Contents!A3 -> Released at 11:30 am (Canberra time) Fri 15 March 2024
A4: Table 68 Defendants sentenced to custody in a correctional institution – Magistrates' Courts, Selected principal offence by sentence length, States and territories, 2022–23
B5: Under 3 months | C5: 3 to under 6 months | D5: 6 to under 12 months | E5: 1 to under 2 years | F5: 2 years & over | G5: Total | H5: Mean | I5: Median
A6: Selected principal offence | B6: (no.) | C6: (no.) | D6: (no.) | E6: (no.) | F6: (no.) | G6: (no.) | H6: (months) | I6: (months)
B7: Australia
A8: 02 Acts intended to cause injury | B8: 1273 | C8: 2315 | D8: 3409 | E8: 2700 | F8: 277 | G8: 10146 | H8: 8.3 | I8: 7
A9: 021 Assault | B9: 1174 | C9: 2102 | D9: 2973 | E9: 2407 | F9: 254 | G9: 9073 | H9: 8.3 | I9: 7
A10: 03 Sexual assault and related offences | B10: 47 | C10: 84 | D10: 148 | E10: 188 | F10: 26 | G10: 500 | H10: 10.1 | I10: 9
A11: 031 Sexual assault | B11: 17 | C11: 37 | D11: 86 | E11: 119 | F11: 18 | G11: 284 | H11: 11 | I11: 10
A12: 04 Dangerous/negligent acts | B12: 163 | C12: 279 | D12: 648 | E12: 564 | F12: 94 | G12: 1776 | H12: 9.8 | I12: 9
A13: 05 Abduction/harassment | B13: 140 | C13: 143 | D13: 171 | E13: 63 | F13: 3 | G13: 516 | H13: 5.7 | I13: 4.9
A14: 053 Harassment and threatening behaviour | B14: 135 | C14: 138 | D14: 153 | E14: 50 | F14: 3 | G14: 482 | H14: 5.4 | I14: 4
A15: 07 Unlawful entry with intent | B15: 275 | C15: 371 | D15: 918 | E15: 1228 | F15: 372 | G15: 3234 | H15: 11.8 | I15: 12
A16: 08 Theft | B16: 1133 | C16: 843 | D16: 1053 | E16: 552 | F16: 50 | G16: 3792 | H16: 5.8 | I16: 4
A17: 081 Motor vehicle theft and related offences | B17: 205 | C17: 229 | D17: 440 | E17: 357 | F17: 37 | G17: 1279 | H17: 8.3 | I17: 7
A18: 082 Theft (except motor vehicles) | B18: 711 | C18: 475 | D18: 495 | E18: 136 | F18: 7 | G18: 1941 | H18: 4.5 | I18: 3
A19: 09 Fraud/deception | B19: 242 | C19: 205 | D19: 237 | E19: 176 | F19: 30 | G19: 893 | H19: 6.9 | I19: 5.6
... A35: All principal offences | B35: 6753 | C35: 6895 | D35: 9816 | E35: 6907 | F35: 957 | G35: 32923 | H35: 7.4 | I35: 6
A36: All principal offences (%) | B36: 20.5 | C36: 20.9 | D36: 29.8 | E36: 21 | F36: 2.9 | G36: 100 | H36: .. | I36: ..
B37: New South Wales
A38: 02 Acts intended to cause injury | B38: 178 | C38: 468 | D38: 1242 | E38: 1229 | F38: 87 | G38: 3212 | H38: 9.9 | I38: 9
A39: 03 Sexual assault and related offences | B39: 4 | C39: 11 | D39: 71 | E39: 154 | F39: 16 | G39: 260 | H39: 13 | I39: 12
A40: 04 Dangerous/negligent acts | B40: 5 | C40: 45 | D40: 170 | E40: 233 | F40: 22 | G40: 478 | H40: 11.8 | I40: 12
A41: 05 Abduction/harassment | B41: 16 | C41: 24 | D41: 35 | E41: 17 | F41: 3 | G41: 95 | H41: 7.3 | I41: 6
A42: 07 Unlawful entry with intent | B42: 8 | C42: 34 | D42: 207 | E42: 352 | F42: 31 | G42: 631 | H42: 12.4 | I42: 12
A43: 08 Theft | B43: 238 | C43: 323 | D43: 412 | E43: 172 | F43: 11 | G43: 1153 | H43: 6.3 | I43: 6
A44: 09 Fraud/deception | B44: 43 | C44: 74 | D44: 89 | E44: 85 | F44: 7 | G44: 296 | H44: 8.2 | I44: 6.4
A45: 10 Illicit drug offences | B45: 35 | C45: 47 | D45: 126 | E45: 176 | F45: 20 | G45: 399 | H45: 10.7 | I45: 10
A46: 11 Weapons/explosives | B46: 61 | C46: 78 | D46: 106 | E46: 90 | F46: 12 | G46: 349 | H46: 8 | I46: 6
A47: 12 Property damage and environmental pollution | B47: 40 | C47: 55 | D47: 81 | E47: 58 | F47: 8 | G47: 235 | H47: 8.2 | I47: 7
A48: 13 Public order offences | B48: 19 | C48: 43 | D48: 112 | E48: 126 | F48: 8 | G48: 317 | H48: 10.3 | I48: 10
A49: 14 Traffic and vehicle regulatory offences | B49: 56 | C49: 156 | D49: 389 | E49: 68 | F49: 0 | G49: 666 | H49: 6.9 | I49: 7
... A51: All principal offences | B51: 928 | C51: 1633 | D51: 3381 | E51: 2924 | F51: 241 | G51: 9109 | H51: 9 | I51: 9
A52: All principal offences (%) | B52: 10.2 | C52: 17.9 | D52: 37.1 | E52: 32.1 | F52: 2.6 | G52: 100 | H52: .. | I52: ..
B53: Victoria
A54: 02 Acts intended to cause injury | B54: 616 | C54: 431 | D54: 281 | E54: 122 | F54: 10 | G54: 1457 | H54: 4.5 | I54: 3
A55: 03 Sexual assault and related offences | B55: 35 | C55: 52 | D55: 43 | E55: 11 | F55: 6 | G55: 133 | H55: 5.7 | I55: 4
A56: 04 Dangerous/negligent acts | B56: 94 | C56: 116 | D56: 98 | E56: 27 | F56: 3 | G56: 339 | H56: 5.3 | I56: 4
...

Sheet Table 69
A1: Australian Bureau of Statistics
A2: =Contents!A2 -> 45130DO013_202223 Criminal Courts, Australia, 2022–23
A3: =Contents!A3 -> Released at 11:30 am (Canberra time) Fri 15 March 2024
A4: Table 69 Defendants sentenced to custody in a correctional institution – Children's Courts, Selected principal offence by sentence length, States and territories, 2022–23
B5: Under 3 months | C5: 3 to under 6 months | D5: 6 to under 12 months | E5: 1 year & over | F5: Total | G5: Mean | H5: Median
A6: Selected principal offence | B6: (no.) | C6: (no.) | D6: (no.) | E6: (no.) | F6: (no.) | G6: (months) | H6: (months)
B7: Australia
A8: 02 Acts intended to cause injury | B8: 42 | C8: 41 | D8: 57 | E8: 50 | F8: 203 | G8: 8.9 | H8: 6
A9: 021 Assault | B9: 36 | C9: 43 | D9: 53 | E9: 48 | F9: 189 | G9: 9 | H9: 6
A10: 03 Sexual assault and related offences | B10: 3 | C10: 3 | D10: 5 | E10: 18 | F10: 33 | G10: 18.3 | H10: 12
A11: 04 Dangerous/negligent acts | B11: 10 | C11: 25 | D11: 37 | E11: 14 | F11: 83 | G11: 7.3 | H11: 6
A12: 06 Robbery/extortion | B12: 13 | C12: 18 | D12: 50 | E12: 33 | F12: 130 | G12: 8.4 | H12: 7.4
A13: 061 Robbery | B13: 18 | C13: 18 | D13: 50 | E13: 33 | F13: 129 | G13: 8.5 | H13: 7.5
A14: 07 Unlawful entry with intent | B14: 64 | C14: 91 | D14: 100 | E14: 68 | F14: 331 | G14: 6.5 | H14: 6
A15: 08 Theft | B15: 35 | C15: 25 | D15: 23 | E15: 7 | F15: 112 | G15: 4.6 | H15: 4
A16: All principal offences | B16: 193 | C16: 219 | D16: 303 | E16: 204 | F16: 997 | G16: 7.6 | H16: 6
A17: All principal offences (%) | B17: 19.4 | C17: 22 | D17: 30.4 | E17: 20.5 | F17: 100 | G17: .. | H17: ..
B18: New South Wales
A19: 02 Acts intended to cause injury | B19: 9 | C19: 8 | D19: 9 | E19: 16 | F19: 39 | G19: 9.5 | H19: 8.5
A20: 03 Sexual assault and related offences | B20: 0 | C20: 0 | D20: 3 | E20: 4 | F20: 10 | G20: 14 | H20: 12
A21: 04 Dangerous/negligent acts | B21: 0 | C21: 0 | D21: 8 | E21: 8 | F21: 24 | G21: 10 | H21: 9
A22: 06 Robbery/extortion | B22: 0 | C22: 8 | D22: 12 | E22: 7 | F22: 30 | G22: 9 | H22: 8.5
A23: 07 Unlawful entry with intent | B23: 0 | C23: 6 | D23: 40 | E23: 30 | F23: 77 | G23: 10.1 | H23: 10
A24: 08 Theft | B24: 0 | C24: 4 | D24: 4 | E24: 3 | F24: 11 | G24: 8.6 | H24: 9.5
A25: All principal offences | B25: 10 | C25: 30 | D25: 95 | E25: 79 | F25: 214 | G25: 9.8 | H25: 9
A26: All principal offences (%) | B26: 4.7 | C26: 14 | D26: 44.4 | E26: 36.9 | F26: 100 | G26: .. | H26: ..
B27: Victoria
A28: 02 Acts intended to cause injury | B28: 3 | C28: 3 | D28: 4 | E28: 0 | F28: 11 | G28: 6.3 | H28: 6
A29: 03 Sexual assault and related offences | B29: 0 | C29: 0 | D29: 0 | E29: 0 | F29: 0 | G29: 0 | H29: 0
A30: 04 Dangerous/negligent acts | B30: 0 | C30: 3 | D30: 0 | E30: 0 | F30: 4 | G30: 10 | H30: 6.5
A31: 06 Robbery/extortion | B31: 3 | C31: 0 | D31: 0 | E31: 0 | F31: 3 | G31: 3.2 | H31: 2.8
A32: 07 Unlawful entry with intent | B32: 0 | C32: 3 | D32: 0 | E32: 0 | F32: 0
A33: 08 Theft | B33: 0 | C33: 0 | D33: 0 | E33: 0 | F33: 5 | G33: 6 | H33: 3
A34: All principal offences | B34: 7 | C34: 11 | D34: 11 | E34: 3 | F34: 33 | G34: 6.7 | H34: 5.4
A35: All principal offences (%) | B35: 21.2 | C35: 33.3 | D35: 33.3 | E35: 9.1 | F35: 100 | G35: .. | H35: ..
B36: Queensland
A37: 02 Acts intended to cause injury | B37: 8 | C37: 10 | D37: 19 | E37: 20 | F37: 59 | G37: 14 | H37: 8.4
A38: 03 Sexual assault and related offences | B38: 0 | C38: 3 | D38: 0 | E38: 0 | F38: 4 | G38: 26.6 | H38: 9
A39: 04 Dangerous/negligent acts | B39: 4 | C39: 11 | D39: 20 | E39: 0 | F39: 40 | G39: 5.8 | H39: 6
A40: 06 Robbery/extortion | B40: 0 | C40: 3 | D40: 26 | E40: 17 | F40: 38 | G40: 11.1 | H40: 9
...

Sheet Table 70
A1: Australian Bureau of Statistics
A2: =Contents!A2 -> 45130DO013_202223 Criminal Courts, Australia, 2022–23
A3: =Contents!A3 -> Released at 11:30 am (Canberra time) Fri 15 March 2024
A4: Table 70 Defendants sentenced to community service / work, Selected principal offence by sentence length and court level, States and territories, 2022–23
B5: All Courts | I5: Higher Courts | K5: Magistrates' Courts | M5: Children's Courts
B6: Under 40 hours | C6: 40 to under 80 hours | D6: 80 to under 120 hours | E6: 120 hours & over | F6: Total | G6: Mean | H6: Median | I6: Mean | J6: Median | K6: Mean | L6: Median | M6: Mean | N6: Median
A7: Selected principal offence | B7: (no.) | C7: (no.) | D7: (no.) | E7: (no.) | F7: (no.) | G7: (hours) | H7: (hours) | I7: (hours) | J7: (hours) | K7: (hours) | L7: (hours) | M7: (hours) | N7: (hours)
B8: Australia
A9: 02 Acts intended to cause injury | B9: 208 | C9: 1047 | D9: 938 | E9: 939 | F9: 3131 | G9: 99.8 | H9: 100 | I9: 156.3 | J9: 150 | K9: 100.6 | L9: 100 | M9: 44.4 | N9: 40
A10: 021 Assault | B10: 201 | C10: 972 | D10: 824 | E10: 849 | F10: 2847 | G10: 99.2 | H10: 90 | I10: 156.8 | J10: 150 | K10: 100 | L10: 100 | M10: 44.3 | N10: 40
A11: 03 Sexual assault and related offences | B11: 4 | C11: 28 | D11: 58 | E11: 189 | F11: 288 | G11: 163.6 | H11: 150 | I11: 191.5 | J11: 175 | K11: 156.7 | L11: 150 | M11: 56.7 | N11: 50
A12: 031 Sexual assault | B12: 4 | C12: 18 | D12: 32 | E12: 103 | F12: 158 | G12: 161.6 | H12: 150 | I12: 186.8 | J12: 155 | K12: 154.3 | L12: 150 | M12: 56.7 | N12: 50
A13: 04 Dangerous/negligent acts | B13: 50 | C13: 216 | D13: 242 | E13: 247 | F13: 757 | G13: 104.5 | H13: 100 | I13: 203 | J13: 200 | K13: 106 | L13: 100 | M13: 55.9 | N13: 50
A14: 05 Abduction/harassment | B14: 27 | C14: 70 | D14: 60 | E14: 34 | F14: 189 | G14: 83.3 | H14: 80 | I14: 183.3 | J14: 175 | K14: 81.2 | L14: 75 | M14: 30 | N14: 25
A15: 053 Harassment and threatening behaviour | B15: 27 | C15: 65 | D15: 55 | E15: 32 | F15: 180 | G15: 81.2 | H15: 75 | I15: 183.3 | J15: 150 | K15: 80.6 | L15: 75 | M15: 30 | N15: 25
A16: 06 Robbery/extortion | B16: 12 | C16: 31 | D16: 17 | E16: 35 | F16: 89 | G16: 104.2 | H16: 90 | I16: 144.4 | J16: 140 | K16: 123.8 | L16: 122.5 | M16: 49.2 | N16: 50
A17: 061 Robbery | B17: 12 | C17: 26 | D17: 17 | E17: 28 | F17: 77 | G17: 102.2 | H17: 90 | I17: 150.8 | J17: 150 | K17: 121.7 | L17: 122.5 | M17: 49.5 | N17: 50
A18: 07 Unlawful entry with intent | B18: 137 | C18: 254 | D18: 139 | E18: 130 | F18: 661 | G18: 76.9 | H18: 60 | I18: 107.3 | J18: 100 | K18: 91.4 | L18: 80 | M18: 43.3 | N18: 40
A19: 08 Theft | B19: 252 | C19: 513 | D19: 252 | E19: 163 | F19: 1183 | G19: 70.1 | H19: 50 | I19: 154.5 | J19: 100 | K19: 75.9 | L19: 60 | M19: 31.4 | N19: 27.5
A20: 082 Theft (except motor vehicles) | B20: 127 | C20: 352 | D20: 162 | E20: 84 | F20: 723 | G20: 68.6 | H20: 60 | I20: 187.5 | J20: 100 | K20: 70.6 | L20: 60 | M20: 33.2 | N20: 27.5
... A37: All principal offences | B37: 1311 | C37: 4291 | D37: 3175 | E37: 2984 | F37: 11772 | G37: 91.5 | H37: 80 | I37: 171.5 | J37: 150 | K37: 92.8 | L37: 80 | M37: 37 | N37: 30
A38: All principal offences (%) | B38: 11.1 | C38: 36.5 | D38: 27 | E38: 25.3 | F38: 100 | G38: .. | H38: .. | I38: .. | J38: .. | K38: .. | L38: .. | M38: .. | N38: ..
B39: New South Wales
A40: 02 Acts intended to cause injury | B40: 32 | C40: 237 | D40: 351 | E40: 274 | F40: 896 | G40: 107 | H40: 100 | I40: 175 | J40: 200 | K40: 107.2 | L40: 100 | M40: 62.3 | N40: 50
A41: 03 Sexual assault and related offences | B41: 0 | C41: 3 | D41: 25 | E41: 69 | F41: 102 | G41: 172.1 | H41: 150 | I41: 205.7 | J41: 200 | K41: 167.5 | L41: 150
A42: 04 Dangerous/negligent acts | B42: 3 | C42: 35 | D42: 62 | E42: 51 | F42: 148 | G42: 112.3 | H42: 100 | I42: 0 | J42: 0 | K42: 115.7 | L42: 100 | M42: 60 | N42: 50
A43: 05 Abduction/harassment | B43: 0 | C43: 11 | D43: 5 | E43: 8 | F43: 25 | G43: 96.7 | H43: 75 | I43: 0 | J43: 0 | K43: 98.4 | L43: 75
A44: 06 Robbery/extortion | B44: 0 | C44: 12 | D44: 10 | E44: 3 | F44: 21 | G44: 96.5 | H44: 77.5 | K44: 187.5 | L44: 200 | M44: 70 | N44: 67.5
A45: 07 Unlawful entry with intent | B45: 0 | C45: 31 | D45: 33 | E45: 22 | F45: 81 | G45: 101.7 | H45: 100 | I45: 101.7 | J45: 80 | K45: 104.8 | L45: 100 | M45: 74.4 | N45: 55
A46: 08 Theft | B46: 13 | C46: 83 | D46: 69 | E46: 51 | F46: 213 | G46: 92.3 | H46: 80 | K46: 94.6 | L46: 80 | M46: 38.9 | N46: 50
A47: 09 Fraud/deception | B47: 0 | C47: 26 | D47: 55 | E47: 45 | F47: 132 | G47: 124.4 | H47: 100 | I47: 0 | J47: 0 | K47: 125 | L47: 100
A48: 10 Illicit drug offences | B48: 3 | C48: 43 | D48: 61 | E48: 89 | F48: 196 | G48: 129.9 | H48: 100 | I48: 150 | J48: 150 | K48: 129.6 | L48: 100
A49: 11 Weapons/explosives | B49: 0 | C49: 19 | D49: 33 | E49: 19 | F49: 76 | G49: 104.8 | H49: 100 | K49: 100.8 | L49: 100
A50: 12 Property damage and environmental pollution | B50: 7 | C50: 24 | D50: 30 | E50: 20 | F50: 81 | G50: 91.6 | H50: 100 | I50: 0 | J50: 0 | K50: 91.6 | L50: 100
A51: 13 Public order offences | B51: 4 | C51: 37 | D51: 56 | E51: 41 | F51: 140 | G51: 111.7 | H51: 100 | K51: 115 | L51: 100 | M51: 71.5 | N51: 50
A52: 14 Traffic and vehicle regulatory offences | B52: 26 | C52: 242 | D52: 310 | E52: 190 | F52: 764 | G52: 97.8 | H52: 100 | I52: 0 | J52: 0 | K52: 97.8 | L52: 100 | M52: 0 | N52: 0
A53: 15 Offences against justice | B53: 12 | C53: 58 | D53: 67 | E53: 36 | F53: 173 | G53: 97.6 | H53: 100 | I53: 283.3 | J53: 250 | K53: 94.4 | L53: 100 | M53: 0 | N53: 0
A54: All principal offences | B54: 113 | C54: 864 | D54: 1162 | E54: 925 | F54: 3063 | G54: 107.3 | H54: 100 | I54: 182.6 | J54: 150 | K54: 107.3 | L54: 100 | M54: 62.6 | N54: 50
A55: All principal offences (%) | B55: 3.7 | C55: 28.2 | D55: 37.9 | E55: 30.2 | F55: 100 | G55: .. | H55: .. | I55: .. | J55: .. | K55: .. | L55: .. | M55: .. | N55: ..
B56: Victoria
...

Sheet Table 71
A1: Australian Bureau of Statistics
A2: =Contents!A2 -> 45130DO013_202223 Criminal Courts, Australia, 2022–23
A3: =Contents!A3 -> Released at 11:30 am (Canberra time) Fri 15 March 2024
A4: Table 71 Defendants given a fine, Selected principal offence by value of fine and court level, States and territories, 2022–23
B5: All Courts | I5: Higher Courts | K5: Magistrates' Courts | M5: Children's Courts
B6: Less than $250 | C6: $250 to less than $500 | D6: $500 to less than $1,000 | E6: $1,000 & over | F6: Total | G6: Mean | H6: Median | I6: Mean | J6: Median | K6: Mean | L6: Median | M6: Mean | N6: Median
A7: Selected principal offence | B7: (no.) | C7: (no.) | D7: (no.) | E7: (no.) | F7: (no.) | G7: ($) | H7: ($) | I7: ($) | J7: ($) | K7: ($) | L7: ($) | M7: ($) | N7: ($)
B8: Australia
A9: 02 Acts intended to cause injury | B9: 337 | C9: 1375 | D9: 4309 | E9: 3898 | F9: 9920 | G9: 955.32 | H9: 800 | I9: 1705.41 | J9: 1000 | K9: 955.8 | L9: 800 | M9: 305.2 | N9: 200
A10: 021 Assault | B10: 302 | C10: 1203 | D10: 3851 | E10: 3548 | F10: 8908 | G10: 964.72 | H10: 800 | I10: 1705.41 | J10: 1000 | K10: 964.7 | L10: 800 | M10: 332.79 | N10: 200
A11: 03 Sexual assault and related offences | B11: 4 | C11: 15 | D11: 69 | E11: 220 | F11: 306 | G11: 1716.82 | H11: 1200 | I11: 3000 | J11: 2000 | K11: 1637.34 | L11: 1015.75 | M11: 1625 | N11: 1500
A12: 04 Dangerous/negligent acts | B12: 370 | C12: 1292 | D12: 3904 | E12: 7869 | F12: 13438 | G12: 1248.8 | H12: 1000 | I12: 1000 | J12: 1000 | K12: 1252.69 | L12: 1000 | M12: 538.06 | N12: 400
A13: 05 Abduction/harassment | B13: 81 | C13: 188 | D13: 553 | E13: 501 | F13: 1318 | G13: 894.8 | H13: 750 | K13: 895.28 | L13: 750
A14: 053 Harassment and threatening behaviour | B14: 81 | C14: 186 | D14: 554 | E14: 494 | F14: 1314 | G14: 895.43 | H14: 750 | K14: 895.91 | L14: 750
A15: 07 Unlawful entry with intent | B15: 33 | C15: 50 | D15: 184 | E15: 229 | F15: 497 | G15: 1078.89 | H15: 800 | I15: 0 | J15: 0 | K15: 1085.66 | L15: 800 | M15: 747 | N15: 110
A16: 08 Theft | B16: 3232 | C16: 4509 | D16: 4769 | E16: 1991 | F16: 14501 | G16: 560.06 | H16: 400 | I16: 850 | J16: 1000 | K16: 562.41 | L16: 400 | M16: 215.3 | N16: 110
A17: 081 Motor vehicle theft and related offences | B17: 28 | C17: 76 | D17: 248 | E17: 221 | F17: 577 | G17: 995.97 | H17: 800 | K17: 1016.45 | L17: 800 | M17: 384.74 | N17: 200
A18: 082 Theft (except motor vehicles) | B18: 2880 | C18: 3643 | D18: 3550 | E18: 1290 | F18: 11360 | G18: 512.62 | H18: 400 | K18: 514.75 | L18: 400 | M18: 168.01 | N18: 100
A19: 083 Receive or handle proceeds of crime | B19: 324 | C19: 791 | D19: 971 | E19: 472 | F19: 2550 | G19: 670.14 | H19: 500 | I19: 937.5 | J19: 1000 | K19: 672.38 | L19: 500 | M19: 221.33 | N19: 100
A20: 09 Fraud/deception | B20: 200 | C20: 483 | D20: 1079 | E20: 1195 | F20: 2951 | G20: 1510.02 | H20: 750 | I20: 8700 | J20: 3000 | K20: 1493.95 | L20: 750 | M20: 212.5 | N20: 200
A21: 091 Obtain benefit by deception | B21: 140 | C21: 360 | D21: 756 | E21: 686 | F21: 1940 | G21: 1144.87 | H21: 700 | I21: 8514.29 | J21: 3000 | K21: 1121.46 | L21: 700 | M21: 207.14 | N21: 200
A22: 10 Illicit drug offences | B22: 4252 | C22: 7234 | D22: 7255 | E22: 2306 | F22: 21052 | G22: 527.94 | H22: 400 | I22: 1931.39 | J22: 1625 | K22: 523.46 | L22: 400 | M22: 181.27 | N22: 100
A23: 104 Possess and/or use illicit drugs | B23: 2859 | C23: 5590 | D23: 5966 | E23: 1337 | F23: 15752 | G23: 499.28 | H23: 400 | I23: 1362.5 | J23: 1000 | K23: 499 | L23: 400 | M23: 132.96 | N23: 100
A24: 11 Weapons/explosives | B24: 719 | C24: 1494 | D24: 2377 | E24: 1204 | F24: 5788 | G24: 679.44 | H24: 500 | I24: 2964.18 | J24: 2500 | K24: 676.23 | L24: 500 | M24: 265.63 | N24: 200
A25: 12 Property damage and environmental pollution | B25: 510 | C25: 1283 | D25: 2281 | E25: 1238 | F25: 5305 | G25: 1113.1 | H25: 500 | I25: 806.25 | J25: 500 | K25: 1118.85 | L25: 513 | M25: 360.46 | N25: 200
A26: 13 Public order offences | B26: 1832 | C26: 3029 | D26: 3955 | E26: 1316 | F26: 10125 | G26: 594.07 | H26: 500 | I26: 1608.33 | J26: 1000 | K26: 594.89 | L26: 500 | M26: 205.54 | N26: 100
A27: 131 Disorderly conduct | B27: 949 | C27: 1494 | D27: 2460 | E27: 838 | F27: 5739 | G27: 579.18 | H27: 500 | I27: 930 | J27: 1000 | K27: 580.96 | L27: 500 | M27: 206.41 | N27: 100
A28: 133 Offensive conduct | B28: 563 | C28: 1143 | D28: 1105 | E28: 326 | F28: 3141 | G28: 618.52 | H28: 400 | K28: 617.79 | L28: 400 | M28: 200 | N28: 150
A29: 14 Traffic and vehicle regulatory offences | B29: 16519 | C29: 42060 | D29: 48861 | E29: 28584 | F29: 136023 | G29: 700.68 | H29: 500 | I29: 2912.5 | J29: 900 | K29: 701.44 | L29: 500 | M29: 348.29 | N29: 210
A30: 141 Driver licence offences | B30: 5869 | C30: 15222 | D30: 15248 | E30: 8526 | F30: 44867 | G30: 610.32 | H30: 500 | I30: 0 | J30: 0 | K30: 611.79 | L30: 500 | M30: 223.14 | N30: 100
A31: 143 Regulatory driving offences | B31: 10084 | C31: 25577 | D31: 32248 | E31: 19673 | F31: 87586 | G31: 752.14 | H31: 507 | I31: 2912.5 | J31: 900 | K31: 752.44 | L31: 507 | M31: 504.99 | N31: 400
A32: 15 Offences against justice | B32: 3216 | C32: 6385 | D32: 8248 | E32: 3604 | F32: 21459 | G32: 757.05 | H32: 500 | I32: 3457.14 | J32: 3000 | K32: 756.48 | L32: 500 | M32: 574.59 | N32: 275
A33: 153 Breach of violence and non-violence orders | B33: 1271 | C33: 3958 | D33: 5755 | E33: 1699 | F33: 12681 | G33: 584.66 | H33: 500 | K33: 584.91 | L33: 500 | M33: 225 | N33: 100
A34: 156 Offences against justice procedures | B34: 1686 | C34: 2114 | D34: 1960 | E34: 1122 | F34: 6883 | G34: 635.53 | H34: 400 | I34: 3640 | J34: 3000 | K34: 632.76 | L34: 400 | M34: 818.64 | N34: 450
A35: All principal offences | B35: 31746 | C35: 70736 | D35: 89747 | E35: 57094 | F35: 249325 | G35: 910.5 | H35: 500 | I35: 83738.84 | J35: 2000 | K35: 827.1 | L35: 500 | M35: 350.8 | N35: 200
A36: All principal offences (%) | B36: 12.7 | C36: 28.4 | D36: 36 | E36: 22.9 | F36: 100
B37: New South Wales
A38: 02 Acts intended to cause injury | B38: 130 | C38: 510 | D38: 1583 | E38: 965 | F38: 3188 | G38: 760.14 | H38: 700 | I38: 0 | J38: 0 | K38: 764.11 | L38: 700 | M38: 258 | N38: 200
A39: 03 Sexual assault and related offences | B39: 4 | C39: 4 | D39: 13 | E39: 34 | F39: 58 | G39: 1286.49 | H39: 1000 | I39: 0 | J39: 0 | K39: 1286.49 | L39: 1000 | M39: 0 | N39: 0
A40: 04 Dangerous/negligent acts | B40: 84 | C40: 274 | D40: 476 | E40: 301 | F40: 1137 | G40: 712.48 | H40: 600 | I40: 0 | J40: 0 | K40: 713.02 | L40: 600
...

Sheet Table 72
A1: Australian Bureau of Statistics
A2: =Contents!A2 -> 45130DO013_202223 Criminal Courts, Australia, 2022–23
A3: =Contents!A3 -> Released at 11:30 am (Canberra time) Fri 15 March 2024
A4: Table 72 Defendants sentenced to custody in a correctional institution (excluding traffic offences), Selected principal offence by Indigenous status and sentence length, Selected states and territories, 2022–23
B5: Aboriginal & Torres Strait Islander | I5: Non-Indigenous | P5: Total
B6: Under 6 months | C6: 6 to under 12 months | D6: 1 to under 5 years | E6: 5 years & over | F6: Total | G6: Mean | H6: Median | I6: Under 6 months | J6: 6 to under 12 months | K6: 1 to under 5 years | L6: 5 years & over | M6: Total | N6: Mean | O6: Median | P6: Under 6 months | Q6: 6 to under 12 months | R6: 1 to under 5 years | S6: 5 years & over | T6: Total | U6: Mean | V6: Median
A7: Selected principal offence | B7: (no.) | C7: (no.) | D7: (no.) | E7: (no.) | F7: (no.) | G7: (months) | H7: (months) | I7: (no.) | J7: (no.) | K7: (no.) | L7: (no.) | M7: (no.) | N7: (months) | O7: (months) | P7: (no.) | Q7: (no.) | R7: (no.) | S7: (no.) | T7: (no.) | U7: (months) | V7: (months)
B8: New South Wales
A9: 01 Homicide and related offences | B9: 0 | C9: 0 | D9: 0 | E9: 7 | F9: 9 | G9: 134.7 | H9: 112.5 | I9: 0 | J9: 0 | K9: 4 | L9: 48 | M9: 60 | N9: 186.4 | O9: 192 | P9: 0 | Q9: 0 | R9: 17 | S9: 68 | T9: 84 | U9: 163.5 | V9: 153
A10: 02 Acts intended to cause injury | B10: 320 | C10: 544 | D10: 633 | E10: 11 | F10: 1510 | G10: 10.9 | H10: 9 | I10: 335 | J10: 696 | K10: 868 | L10: 26 | M10: 1924 | N10: 12.3 | O10: 10 | P10: 674 | Q10: 1264 | R10: 1551 | S10: 36 | T10: 3527 | U10: 11.7 | V10: 10
A11: 03 Sexual assault and related offences | B11: 7 | C11: 21 | D11: 77 | E11: 29 | F11: 125 | G11: 37.6 | H11: 22 | I11: 16 | J11: 63 | K11: 389 | L11: 159 | M11: 626 | N11: 41.2 | O11: 30 | P11: 24 | Q11: 83 | R11: 494 | S11: 195 | T11: 798 | U11: 40.4 | V11: 30
A12: 04 Dangerous/negligent acts | B12: 0 | C12: 0 | D12: 0 | E12: 0 | F12: 0 | G12: 0 | H12: 0 | I12: 0 | J12: 0 | K12: 3 | L12: 0 | M12: 3 | P12: 0 | Q12: 0 | R12: 3 | S12: 0 | T12: 3
A13: 05 Abduction/harassment | B13: 15 | C13: 19 | D13: 29 | E13: 4 | F13: 60 | G13: 19.6 | H13: 9 | I13: 22 | J13: 16 | K13: 46 | L13: 10 | M13: 97 | N13: 25.6 | O13: 12.5 | P13: 36 | Q13: 37 | R13: 71 | S13: 17 | T13: 162 | U13: 23.1 | V13: 12
A14: 06 Robbery/extortion | B14: 4 | C14: 16 | D14: 105 | E14: 11 | F14: 140 | G14: 31.7 | H14: 32 | I14: 0 | J14: 9 | K14: 102 | L14: 9 | M14: 125 | N14: 33.6 | O14: 34 | P14: 4 | Q14: 26 | R14: 221 | S14: 23 | T14: 282 | U14: 32.8 | V14: 34
A15: 07 Unlawful entry with intent | B15: 31 | C15: 128 | D15: 280 | E15: 4 | F15: 447 | G15: 15 | H15: 12 | I15: 19 | J15: 117 | K15: 293 | L15: 12 | M15: 440 | N15: 18.9 | O15: 14 | P15: 53 | Q15: 249 | R15: 588 | S15: 18 | T15: 907 | U15: 16.9 | V15: 13
A16: 08 Theft | B16: 227 | C16: 160 | D16: 77 | E16: 0 | F16: 461 | G16: 6.5 | H16: 6 | I16: 309 | J16: 244 | K16: 132 | L16: 3 | M16: 695 | N16: 7.6 | O16: 6 | P16: 561 | Q16: 421 | R16: 224 | S16: 6 | T16: 1216 | U16: 7.4 | V16: 6
A17: 09 Fraud/deception | B17: 41 | C17: 33 | D17: 10 | E17: 0 | F17: 84 | G17: 6.3 | H17: 6 | I17: 68 | J17: 51 | K17: 86 | L17: 3 | M17: 210 | N17: 13.1 | O17: 9 | P17: 120 | Q17: 88 | R17: 123 | S17: 3 | T17: 332 | U17: 11.6 | V17: 8
A18: 10 Illicit drug offences | B18: 14 | C18: 25 | D18: 47 | E18: 3 | F18: 94 | G18: 16.2 | H18: 12 | I18: 66 | J18: 96 | K18: 376 | L18: 89 | M18: 631 | N18: 29.4 | O18: 18 | P18: 85 | Q18: 127 | R18: 442 | S18: 110 | T18: 762 | U18: 30.1 | V18: 18
A19: 11 Weapons/explosives | B19: 50 | C19: 36 | D19: 40 | E19: 3 | F19: 124 | G19: 10.7 | H19: 7 | I19: 86 | J19: 69 | K19: 120 | L19: 4 | M19: 279 | N19: 13.9 | O19: 9 | P19: 138 | Q19: 107 | R19: 161 | S19: 14 | T19: 417 | U19: 13.4 | V19: 8
A20: 12 Property damage and environmental pollution | B20: 41 | C20: 37 | D20: 33 | E20: 0 | F20: 105 | G20: 8.6 | H20: 8 | I20: 48 | J20: 41 | K20: 54 | L20: 0 | M20: 148 | N20: 10.2 | O20: 8 | P20: 91 | Q20: 81 | R20: 82 | S20: 0 | T20: 255 | U20: 9.7 | V20: 8
A21: 13 Public order offences | B21: 26 | C21: 63 | D21: 47 | E21: 0 | F21: 135 | G21: 10.1 | H21: 9 | I21: 42 | J21: 68 | K21: 112 | L21: 0 | M21: 213 | N21: 11.7 | O21: 12 | P21: 63 | Q21: 130 | R21: 165 | S21: 0 | T21: 363 | U21: 11.1 | V21: 10
A22: 15 Offences against justice | B22: 218 | C22: 116 | D22: 51 | E22: 0 | F22: 386 | G22: 5.8 | H22: 4 | I22: 274 | J22: 200 | K22: 74 | L22: 3 | M22: 554 | N22: 6.9 | O22: 6 | P22: 498 | Q22: 325 | R22: 131 | S22: 6 | T22: 965 | U22: 6.6 | V22: 5
A23: 16 Miscellaneous offences | B23: 7 | C23: 0 | D23: 0 | E23: 0 | F23: 7 | G23: 3 | H23: 3 | I23: 0 | J23: 4 | K23: 10 | L23: 0 | M23: 12 | N23: 17.7 | O23: 15 | P23: 5 | Q23: 0 | R23: 10 | S23: 0 | T23: 22 | U23: 13.3 | V23: 10
A24: All principal offences | B24: 993 | C24: 1196 | D24: 1436 | E24: 74 | F24: 3698 | G24: 12.4 | H24: 9 | I24: 1287 | J24: 1678 | K24: 2672 | L24: 374 | M24: 6015 | N24: 18.8 | O24: 12 | P24: 2365 | Q24: 2940 | R24: 4294 | S24: 492 | T24: 10093 | U24: 16.8 | V24: 10
A25: All principal offences (%) | B25: 26.9 | C25: 32.3 | D25: 38.8 | E25: 2 | F25: 100 | G25: .. | H25: .. | I25: 21.4 | J25: 27.9 | K25: 44.4 | L25: 6.2 | M25: 100 | N25: .. | O25: .. | P25: 23.4 | Q25: 29.1 | R25: 42.5 | S25: 4.9 | T25: 100 | U25: .. | V25: ..
B26: Queensland
A27: 01 Homicide and related offences | B27: 0 | C27: 0 | D27: 0 | E27: 15 | F27: 15 | G27: 111.3 | H27: 108 | I27: 0 | J27: 0 | K27: 5 | L27: 46 | M27: 52 | N27: 101.2 | O27: 102 | P27: 0 | Q27: 0 | R27: 5 | S27: 61 | T27: 60 | U27: 104.2 | V27: 108
A28: 02 Acts intended to cause injury | B28: 224 | C28: 451 | D28: 884 | E28: 21 | F28: 1574 | G28: 14.5 | H28: 12 | I28: 162 | J28: 459 | K28: 989 | L28: 63 | M28: 1678 | N28: 18.2 | O28: 12 | P28: 387 | Q28: 917 | R28: 1893 | S28: 81 | T28: 3282 | U28: 16.5 | V28: 12
A29: 03 Sexual assault and related offences | B29: 11 | C29: 22 | D29: 47 | E29: 31 | F29: 103 | G29: 37.2 | H29: 18 | I29: 21 | J29: 60 | K29: 234 | L29: 94 | M29: 412 | N29: 37.3 | O29: 24 | P29: 28 | Q29: 81 | R29: 293 | S29: 129 | T29: 527 | U29: 37.4 | V29: 24
A30: 04 Dangerous/negligent acts | B30: 16 | C30: 11 | D30: 3 | E30: 0 | F30: 39 | G30: 6.2 | H30: 6 | I30: 16 | J30: 24 | K30: 22 | L30: 0 | M30: 60 | N30: 8.8 | O30: 6 | P30: 40 | Q30: 39 | R30: 24 | S30: 0 | T30: 99 | U30: 7.7 | V30: 6
A31: 05 Abduction/harassment | B31: 10 | C31: 24 | D31: 17 | E31: 0 | F31: 48 | G31: 11.8 | H31: 9 | I31: 37 | J31: 51 | K31: 36 | L31: 0 | M31: 123 | N31: 9.7 | O31: 6 | P31: 41 | Q31: 72 | R31: 54 | S31: 0 | T31: 170 | U31: 10.3 | V31: 7
A32: 06 Robbery/extortion | B32: 3 | C32: 19 | D32: 138 | E32: 14 | F32: 178 | G32: 32.5 | H32: 36 | I32: 5 | J32: 24 | K32: 196 | L32: 18 | M32: 239 | N32: 32.7 | O32: 33 | P32: 7 | Q32: 42 | R32: 336 | S32: 31 | T32: 426 | U32: 32.6 | V32: 36
A33: 07 Unlawful entry with intent | B33: 102 | C33: 154 | D33: 394 | E33: 0 | F33: 654 | G33: 14.3 | H33: 12 | I33: 70 | J33: 222 | K33: 681 | L33: 18 | M33: 990 | N33: 17.2 | O33: 15 | P33: 169 | Q33: 384 | R33: 1095 | S33: 18 | T33: 1659 | U33: 16.1 | V33: 12
A34: 08 Theft | B34: 142 | C34: 162 | D34: 131 | E34: 0 | F34: 433 | G34: 8.2 | H34: 6 | I34: 274 | J34: 361 | K34: 310 | L34: 3 | M34: 955 | N34: 9.4 | O34: 8 | P34: 421 | Q34: 528 | R34: 445 | S34: 3 | T34: 1394 | U34: 9 | V34: 7
A35: 09 Fraud/deception | B35: 24 | C35: 20 | D35: 5 | E35: 0 | F35: 49 | G35: 6.3 | H35: 6 | I35: 58 | J35: 68 | K35: 93 | L35: 20 | M35: 243 | N35: 18 | O35: 9 | P35: 94 | Q35: 103 | R35: 135 | S35: 22 | T35: 351 | U35: 17 | V35: 9
A36: 10 Illicit drug offences | B36: 38 | C36: 17 | D36: 72 | E36: 7 | F36: 137 | G36: 20.5 | H36: 15 | I36: 155 | J36: 155 | K36: 770 | L36: 141 | M36: 1220 | N36: 28.4 | O36: 24 | P36: 194 | Q36: 172 | R36: 848 | S36: 154 | T36: 1371 | U36: 27.8 | V36: 21
A37: 11 Weapons/explosives | B37: 17 | C37: 5 | D37: 12 | E37: 0 | F37: 30 | G37: 7.5 | H37: 7.8 | I37: 46 | J37: 34 | K37: 54 | L37: 0 | M37: 135 | N37: 9.6 | O37: 7.5 | P37: 61 | Q37: 38 | R37: 69 | S37: 0 | T37: 167 | U37: 9.2 | V37: 8
A38: 12 Property damage and environmental pollution | B38: 42 | C38: 56 | D38: 37 | E38: 0 | F38: 134 | G38: 11 | H38: 6 | I38: 59 | J38: 52 | K38: 62 | L38: 0 | M38: 174 | N38: 14.9 | O38: 6 | P38: 101 | Q38: 108 | R38: 100 | S38: 0 | T38: 317 | U38: 13.2 | V38: 6
... A40: 15 Offences against justice | B40: 497 | C40: 433 | D40: 151 | E40: 0 | F40: 1080 | G40: 6 | H40: 6 | I40: 644 | J40: 594 | K40: 217 | L40: 6 | M40: 1459 | N40: 6.6 | O40: 6 | P40: 1153 | Q40: 1033 | R40: 378 | S40: 6 | T40: 2561 | U40: 6.3 | V40: 6
A41: 16 Miscellaneous offences | B41: 0 | C41: 0 | D41: 0 | E41: 0 | F41: 0 | I41: 7 | J41: 3 | K41: 0 | L41: 0 | M41: 4 | N41: 7.4 | O41: 4 | P41: 5 | Q41: 5 | R41: 4 | S41: 0 | T41: 8 | U41: 8.2 | V41: 6
...
